<?xml version="1.0" encoding="utf-8"?>
<!-- This URDF was automatically created by SolidWorks to URDF Exporter! Originally created by Stephen Brawner (brawner@gmail.com) 
     Commit Version: 1.6.0-4-g7f85cfe  Build Version: 1.6.7995.38578
     For more information, please see http://wiki.ros.org/sw_urdf_exporter -->
<robot
  name="Xuanwu">
  <link
    name="base_link">
    <inertial>
      <origin
        xyz="0.001 0 0.07"
        rpy="0 0 0" />
      <mass
        value="1.894" />
      <inertia
        ixx="0.010281"
        ixy="-0.000026"
        ixz="0.000041"
        iyy="0.015443"
        iyz="0.000023"
        izz="0.006341" />
    </inertial>
    <visual>
      <origin
        xyz="0 0 0"
        rpy="0 0 0" />
      <geometry>
        <mesh
          filename="../meshes/base_link.STL" />
      </geometry>
      <material
        name="">
        <color
          rgba="1 1 1 1" />
      </material>
    </visual>
    <collision>
      <origin
        xyz="0 0 0.2"
        rpy="0 0 0" />
      <geometry>
        <box size="0.1 0.2 0.2"/>
      </geometry>
    </collision>
  </link>
  <link
    name="link_1">
    <inertial>
      <origin
        xyz="-0.007 -0.06 -0.073"
        rpy="0 0 0" />
      <mass
        value="0.547" />
      <inertia
        ixx="0.002384"
        ixy="0.000245"
        ixz="0.000302"
        iyy="0.001710"
        iyz="-0.000927"
        izz="0.001161" />
    </inertial>
    <visual>
      <origin
        xyz="0 0 0"
        rpy="0 0 0" />
      <geometry>
        <mesh
          filename="../meshes/link_1.STL" />
      </geometry>
      <material
        name="">
        <color
          rgba="1 1 1 1" />
      </material>
    </visual>
    <!-- <collision>
      <origin
        xyz="0 0 0"
        rpy="0 0 0" />
      <geometry>
        <mesh
          filename="../meshes/link_1.STL" />
      </geometry>
    </collision> -->
  </link>
  <joint
    name="joint_1"
    type="revolute">
    <origin
      xyz="-0.073 0 -0.001"
      rpy="0 0 0" />
    <parent
      link="base_link" />
    <child
      link="link_1" />
    <axis
      xyz="0 0 1" />
    <limit
      lower="-0.5"
      upper="0.5"
      effort="7"
      velocity="12" />
  </joint>
  <link
    name="link_2">
    <inertial>
      <origin
        xyz="0 0.077 0"
        rpy="0 0 0" />
      <mass
        value="0.378" />
      <inertia
        ixx="0.000152"
        ixy="0"
        ixz="0"
        iyy="0.000106"
        iyz="0"
        izz="0.000167" />
    </inertial>
    <visual>
      <origin
        xyz="0 0 0"
        rpy="0 0 0" />
      <geometry>
        <mesh
          filename="../meshes/link_2.STL" />
      </geometry>
      <material
        name="">
        <color
          rgba="1 1 1 1" />
      </material>
    </visual>
    <!-- <collision>
      <origin
        xyz="0 0 0"
        rpy="0 0 0" />
      <geometry>
        <mesh
          filename="../meshes/link_2.STL" />
      </geometry>
    </collision> -->
  </link>
  <joint
    name="joint_2"
    type="revolute">
    <origin
      xyz="0 -0.083 -0.11"
      rpy="0 0 0" />
    <parent
      link="link_1" />
    <child
      link="link_2" />
    <axis
      xyz="0 1 0" />
    <limit
      lower="-0.7"
      upper="0.7"
      effort="7"
      velocity="12" />
  </joint>
  <link
    name="link_3">
    <inertial>
      <origin
        xyz="0 0 -0.1504"
        rpy="0 0 0" />
      <mass
        value="0.436" />
      <inertia
        ixx="0.001403"
        ixy="0"
        ixz="-0.000024"
        iyy="0.001465"
        iyz="0"
        izz="0.000207" />
    </inertial>
    <visual>
      <origin
        xyz="0 0 0"
        rpy="0 0 0" />
      <geometry>
        <mesh
          filename="../meshes/link_3.STL" />
      </geometry>
      <material
        name="">
        <color
          rgba="1 1 1 1" />
      </material>
    </visual>
    <!-- <collision>
      <origin
        xyz="0 0 0"
        rpy="0 0 0" />
      <geometry>
        <mesh
          filename="../meshes/link_3.STL" />
      </geometry>
    </collision> -->
  </link>
  <joint
    name="joint_3"
    type="revolute">
    <origin
      xyz="0 0.082 0"
      rpy="0 0 0" />
    <parent
      link="link_2" />
    <child
      link="link_3" />
    <axis
      xyz="1 0 0" />
    <limit
      lower="-0.25"
      upper="1.57"
      effort="7"
      velocity="12" />
  </joint>
  <link
    name="link_4">
    <inertial>
      <origin
        xyz="0 0 -0.1504"
        rpy="0 0 0" />
      <mass
        value="0.436" />
      <inertia
        ixx="0.001403"
        ixy="0"
        ixz="-0.000024"
        iyy="0.001465"
        iyz="0"
        izz="0.000207" />
    </inertial>
    <visual>
      <origin
        xyz="0 0 0"
        rpy="0 0 0" />
      <geometry>
        <mesh
          filename="../meshes/link_4.STL" />
      </geometry>
      <material
        name="">
        <color
          rgba="1 1 1 1" />
      </material>
    </visual>
    <!-- <collision>
      <origin
        xyz="0 0 0"
        rpy="0 0 0" />
      <geometry>
        <mesh
          filename="../meshes/link_4.STL" />
      </geometry>
    </collision> -->
  </link>
  <joint
    name="joint_4"
    type="revolute">
    <origin
      xyz="0 0 -0.18"
      rpy="0 0 0" />
    <parent
      link="link_3" />
    <child
      link="link_4" />
    <axis
      xyz="1 0 0" />
    <limit
      lower="-1.57"
      upper="1.57"
      effort="7"
      velocity="12" />
  </joint>
  <link
    name="link_5">
    <inertial>
      <origin
        xyz="0.04 0.03 0.07"
        rpy="0 0 0" />
      <mass
        value="0.105" />
      <inertia
        ixx="0.000202"
        ixy="0"
        ixz="-0.000008"
        iyy="0.000197"
        iyz="0"
        izz="0.000211" />
    </inertial>
    <visual>
      <origin
        xyz="0 0 0"
        rpy="0 0 0" />
      <geometry>
        <mesh
          filename="../meshes/link_5.STL" />
      </geometry>
      <material
        name="">
        <color
          rgba="1 1 1 1" />
      </material>
    </visual>
    <collision>
      <origin
        xyz="0 0 0"
        rpy="0 0 0" />
      <geometry>
        <mesh
          filename="../meshes/link_5.STL" />
      </geometry>
    </collision>
  </link>
  <joint
    name="joint_5"
    type="revolute">
    <origin
      xyz="0 0 -0.18"
      rpy="0 0 0" />
    <parent
      link="link_4" />
    <child
      link="link_5" />
    <axis
      xyz="1 0 0" />
    <limit
      lower="-1.57"
      upper="1.57"
      effort="7"
      velocity="12" />
  </joint>
  <link
    name="link_6">
    <inertial>
      <origin
        xyz="0.007 -0.06 -0.074"
        rpy="0 0 0" />
      <mass
        value="0.547" />
      <inertia
        ixx="0.002384"
        ixy="-0.000245"
        ixz="-0.000302"
        iyy="0.001710"
        iyz="-0.000927"
        izz="0.001161" />
    </inertial>
    <visual>
      <origin
        xyz="0 0 0"
        rpy="0 0 0" />
      <geometry>
        <mesh
          filename="../meshes/link_6.STL" />
      </geometry>
      <material
        name="">
        <color
          rgba="1 1 1 1" />
      </material>
    </visual>
    <!-- <collision>
      <origin
        xyz="0 0 0"
        rpy="0 0 0" />
      <geometry>
        <mesh
          filename="../meshes/link_6.STL" />
      </geometry>
    </collision> -->
  </link>
  <joint
    name="joint_6"
    type="revolute">
    <origin
      xyz="0.073 0 -0.001"
      rpy="0 0 0" />
    <parent
      link="base_link" />
    <child
      link="link_6" />
    <axis
      xyz="0 0 1" />
    <limit
      lower="-0.5"
      upper="0.5"
      effort="7"
      velocity="12" />
  </joint>
  <link
    name="link_7">
    <inertial>
      <origin
        xyz="0 0.077 0"
        rpy="0 0 0" />
      <mass
        value="0.378" />
      <inertia
        ixx="0.000152"
        ixy="0"
        ixz="0"
        iyy="0.000106"
        iyz="0"
        izz="0.000167" />
    </inertial>
    <visual>
      <origin
        xyz="0 0 0"
        rpy="0 0 0" />
      <geometry>
        <mesh
          filename="../meshes/link_7.STL" />
      </geometry>
      <material
        name="">
        <color
          rgba="1 1 1 1" />
      </material>
    </visual>
    <!-- <collision>
      <origin
        xyz="0 0 0"
        rpy="0 0 0" />
      <geometry>
        <mesh
          filename="../meshes/link_7.STL" />
      </geometry>
    </collision> -->
  </link>
  <joint
    name="joint_7"
    type="revolute">
    <origin
      xyz="0 -0.083 -0.11"
      rpy="0 0 0" />
    <parent
      link="link_6" />
    <child
      link="link_7" />
    <axis
      xyz="0 1 0" />
    <limit
      lower="-0.7"
      upper="0.7"
      effort="7"
      velocity="12" />
  </joint>
  <link
    name="link_8">
    <inertial>
      <origin
        xyz="0 0 -0.1504"
        rpy="0 0 0" />
      <mass
        value="0.436" />
      <inertia
        ixx="0.001403"
        ixy="0"
        ixz="0.000024"
        iyy="0.001465"
        iyz="0"
        izz="0.000207" />
    </inertial>
    <visual>
      <origin
        xyz="0 0 0"
        rpy="0 0 0" />
      <geometry>
        <mesh
          filename="../meshes/link_8.STL" />
      </geometry>
      <material
        name="">
        <color
          rgba="1 1 1 1" />
      </material>
    </visual>
    <!-- <collision>
      <origin
        xyz="0 0 0"
        rpy="0 0 0" />
      <geometry>
        <mesh
          filename="../meshes/link_8.STL" />
      </geometry>
    </collision> -->
  </link>
  <joint
    name="joint_8"
    type="revolute">
    <origin
      xyz="0 0.082 0"
      rpy="0 0 0" />
    <parent
      link="link_7" />
    <child
      link="link_8" />
    <axis
      xyz="1 0 0" />
    <limit
      lower="-0.25"
      upper="1.57"
      effort="7"
      velocity="12" />
  </joint>
  <link
    name="link_9">
    <inertial>
      <origin
        xyz="0 0 -0.1504"
        rpy="0 0 0" />
      <mass
        value="0.436" />
      <inertia
        ixx="0.001403"
        ixy="0"
        ixz="0.000024"
        iyy="0.001465"
        iyz="0"
        izz="0.000207" />
    </inertial>
    <visual>
      <origin
        xyz="0 0 0"
        rpy="0 0 0" />
      <geometry>
        <mesh
          filename="../meshes/link_9.STL" />
      </geometry>
      <material
        name="">
        <color
          rgba="1 1 1 1" />
      </material>
    </visual>
    <!-- <collision>
      <origin
        xyz="0 0 0"
        rpy="0 0 0" />
      <geometry>
        <mesh
          filename="../meshes/link_9.STL" />
      </geometry>
    </collision> -->
  </link>
  <joint
    name="joint_9"
    type="revolute">
    <origin
      xyz="0 0 -0.18"
      rpy="0 0 0" />
    <parent
      link="link_8" />
    <child
      link="link_9" />
    <axis
      xyz="1 0 0" />
    <limit
      lower="-1.57"
      upper="1.57"
      effort="7"
      velocity="12" />
  </joint>
  <link
    name="link_10">
    <inertial>
      <origin
        xyz="0 0 -0.053"
        rpy="0 0 0" />
      <mass
        value="0.105" />
      <inertia
        ixx="0.000202"
        ixy="0"
        ixz="0.000008"
        iyy="0.000197"
        iyz="0"
        izz="0.000211" />
    </inertial>
    <visual>
      <origin
        xyz="0 0 0"
        rpy="0 0 0" />
      <geometry>
        <mesh
          filename="../meshes/link_10.STL" />
      </geometry>
      <material
        name="">
        <color
          rgba="1 1 1 1" />
      </material>
    </visual>
    <collision>
      <origin
        xyz="0 0 0"
        rpy="0 0 0" />
      <geometry>
        <mesh
          filename="../meshes/link_10.STL" />
      </geometry>
    </collision>
  </link>
  <joint
    name="joint_10"
    type="revolute">
    <origin
      xyz="0 0 -0.18"
      rpy="0 0 0" />
    <parent
      link="link_9" />
    <child
      link="link_10" />
    <axis
      xyz="1 0 0" />
    <limit
      lower="-1.57"
      upper="1.57"
      effort="7"
      velocity="12" />
  </joint>
</robot>